[2024-02-20T21:36:02.965+0000] {taskinstance.py:1957} INFO - Dependencies all met for dep_context=non-requeueable deps ti=<TaskInstance: processing_sales.load_data_to_bronze scheduled__2022-08-01T01:00:00+00:00 [queued]>
[2024-02-20T21:36:02.973+0000] {taskinstance.py:1957} INFO - Dependencies all met for dep_context=requeueable deps ti=<TaskInstance: processing_sales.load_data_to_bronze scheduled__2022-08-01T01:00:00+00:00 [queued]>
[2024-02-20T21:36:02.974+0000] {taskinstance.py:2171} INFO - Starting attempt 16 of 19
[2024-02-20T21:36:02.988+0000] {taskinstance.py:2192} INFO - Executing <Task(GCSToBigQueryOperator): load_data_to_bronze> on 2022-08-01 01:00:00+00:00
[2024-02-20T21:36:02.994+0000] {standard_task_runner.py:60} INFO - Started process 1060 to run task
[2024-02-20T21:36:02.998+0000] {standard_task_runner.py:87} INFO - Running: ['***', 'tasks', 'run', 'processing_sales', 'load_data_to_bronze', 'scheduled__2022-08-01T01:00:00+00:00', '--job-id', '30', '--raw', '--subdir', 'DAGS_FOLDER/process_sales.py', '--cfg-path', '/tmp/tmpxj0rab9s']
[2024-02-20T21:36:03.000+0000] {standard_task_runner.py:88} INFO - Job 30: Subtask load_data_to_bronze
[2024-02-20T21:36:03.054+0000] {task_command.py:423} INFO - Running <TaskInstance: processing_sales.load_data_to_bronze scheduled__2022-08-01T01:00:00+00:00 [running]> on host 14ee3b1c5c12
[2024-02-20T21:36:03.132+0000] {taskinstance.py:2481} INFO - Exporting env vars: AIRFLOW_CTX_DAG_OWNER='***' AIRFLOW_CTX_DAG_ID='processing_sales' AIRFLOW_CTX_TASK_ID='load_data_to_bronze' AIRFLOW_CTX_EXECUTION_DATE='2022-08-01T01:00:00+00:00' AIRFLOW_CTX_TRY_NUMBER='16' AIRFLOW_CTX_DAG_RUN_ID='scheduled__2022-08-01T01:00:00+00:00'
[2024-02-20T21:36:03.144+0000] {connection.py:234} WARNING - Connection schemes (type: google_cloud_platform) shall not contain '_' according to RFC3986.
[2024-02-20T21:36:03.146+0000] {base.py:83} INFO - Using connection ID 'google-cloud' for task execution.
[2024-02-20T21:36:03.147+0000] {gcs_to_bigquery.py:379} INFO - Using existing BigQuery table for storing data...
[2024-02-20T21:36:03.148+0000] {logging_mixin.py:188} INFO - VEFORE
[2024-02-20T21:36:03.148+0000] {logging_mixin.py:188} INFO - path /opt/***/etc/credentials.json
[2024-02-20T21:36:03.149+0000] {logging_mixin.py:188} INFO - dict ***
[2024-02-20T21:36:03.149+0000] {logging_mixin.py:188} INFO - {'key_path': '/opt/***/etc/credentials.json', 'keyfile_dict': '***', 'num_retries': 5, 'credential_config_file': '/opt/***/etc/credentials.json', 'project': 'de-07-natalia-sokil', 'scope': 'https://www.googleapis.com/auth/cloud-platform'}
[2024-02-20T21:36:03.150+0000] {logging_mixin.py:188} INFO - ***
[2024-02-20T21:36:03.159+0000] {taskinstance.py:2699} ERROR - Task failed with exception
Traceback (most recent call last):
  File "/home/airflow/.local/lib/python3.8/site-packages/airflow/providers/google/common/hooks/base_google.py", line 268, in get_credentials_and_project_id
    keyfile_dict_json = json.loads(keyfile_dict)
  File "/usr/local/lib/python3.8/json/__init__.py", line 357, in loads
    return _default_decoder.decode(s)
  File "/usr/local/lib/python3.8/json/decoder.py", line 337, in decode
    obj, end = self.raw_decode(s, idx=_w(s, 0).end())
  File "/usr/local/lib/python3.8/json/decoder.py", line 355, in raw_decode
    raise JSONDecodeError("Expecting value", s, err.value) from None
json.decoder.JSONDecodeError: Expecting value: line 1 column 1 (char 0)

During handling of the above exception, another exception occurred:

Traceback (most recent call last):
  File "/home/airflow/.local/lib/python3.8/site-packages/airflow/models/taskinstance.py", line 433, in _execute_task
    result = execute_callable(context=context, **execute_callable_kwargs)
  File "/home/airflow/.local/lib/python3.8/site-packages/airflow/providers/google/cloud/transfers/gcs_to_bigquery.py", line 380, in execute
    self.configuration = self._use_existing_table()
  File "/home/airflow/.local/lib/python3.8/site-packages/airflow/providers/google/cloud/transfers/gcs_to_bigquery.py", line 581, in _use_existing_table
    default_project_id=self.hook.project_id,
  File "/home/airflow/.local/lib/python3.8/site-packages/airflow/providers/google/common/hooks/base_google.py", line 370, in project_id
    _, project_id = self.get_credentials_and_project_id()
  File "/home/airflow/.local/lib/python3.8/site-packages/airflow/providers/google/common/hooks/base_google.py", line 270, in get_credentials_and_project_id
    raise AirflowException("Invalid key JSON.")
airflow.exceptions.AirflowException: Invalid key JSON.
[2024-02-20T21:36:03.164+0000] {taskinstance.py:1138} INFO - Marking task as UP_FOR_RETRY. dag_id=processing_sales, task_id=load_data_to_bronze, execution_date=20220801T010000, start_date=20240220T213602, end_date=20240220T213603
[2024-02-20T21:36:03.177+0000] {standard_task_runner.py:107} ERROR - Failed to execute job 30 for task load_data_to_bronze (Invalid key JSON.; 1060)
[2024-02-20T21:36:03.211+0000] {local_task_job_runner.py:234} INFO - Task exited with return code 1
[2024-02-20T21:36:03.246+0000] {taskinstance.py:3281} INFO - 0 downstream tasks scheduled from follow-on schedule check
