[2024-02-20T20:45:59.076+0000] {taskinstance.py:1957} INFO - Dependencies all met for dep_context=non-requeueable deps ti=<TaskInstance: processing_sales.load_data_to_bronze scheduled__2022-08-01T01:00:00+00:00 [queued]>
[2024-02-20T20:45:59.082+0000] {taskinstance.py:1957} INFO - Dependencies all met for dep_context=requeueable deps ti=<TaskInstance: processing_sales.load_data_to_bronze scheduled__2022-08-01T01:00:00+00:00 [queued]>
[2024-02-20T20:45:59.082+0000] {taskinstance.py:2171} INFO - Starting attempt 3 of 6
[2024-02-20T20:45:59.094+0000] {taskinstance.py:2192} INFO - Executing <Task(GCSToBigQueryOperator): load_data_to_bronze> on 2022-08-01 01:00:00+00:00
[2024-02-20T20:45:59.099+0000] {standard_task_runner.py:60} INFO - Started process 1954 to run task
[2024-02-20T20:45:59.102+0000] {standard_task_runner.py:87} INFO - Running: ['***', 'tasks', 'run', 'processing_sales', 'load_data_to_bronze', 'scheduled__2022-08-01T01:00:00+00:00', '--job-id', '8', '--raw', '--subdir', 'DAGS_FOLDER/process_sales.py', '--cfg-path', '/tmp/tmpdgh35zap']
[2024-02-20T20:45:59.103+0000] {standard_task_runner.py:88} INFO - Job 8: Subtask load_data_to_bronze
[2024-02-20T20:45:59.146+0000] {task_command.py:423} INFO - Running <TaskInstance: processing_sales.load_data_to_bronze scheduled__2022-08-01T01:00:00+00:00 [running]> on host 483c6a14d6cc
[2024-02-20T20:45:59.208+0000] {taskinstance.py:2481} INFO - Exporting env vars: AIRFLOW_CTX_DAG_OWNER='***' AIRFLOW_CTX_DAG_ID='processing_sales' AIRFLOW_CTX_TASK_ID='load_data_to_bronze' AIRFLOW_CTX_EXECUTION_DATE='2022-08-01T01:00:00+00:00' AIRFLOW_CTX_TRY_NUMBER='3' AIRFLOW_CTX_DAG_RUN_ID='scheduled__2022-08-01T01:00:00+00:00'
[2024-02-20T20:45:59.218+0000] {connection.py:234} WARNING - Connection schemes (type: google_cloud_platform) shall not contain '_' according to RFC3986.
[2024-02-20T20:45:59.219+0000] {base.py:83} INFO - Using connection ID 'google-cloud' for task execution.
[2024-02-20T20:45:59.220+0000] {gcs_to_bigquery.py:379} INFO - Using existing BigQuery table for storing data...
[2024-02-20T20:45:59.226+0000] {taskinstance.py:2699} ERROR - Task failed with exception
Traceback (most recent call last):
  File "/home/airflow/.local/lib/python3.8/site-packages/airflow/providers/google/common/hooks/base_google.py", line 259, in get_credentials_and_project_id
    keyfile_dict_json = json.loads(keyfile_dict)
  File "/usr/local/lib/python3.8/json/__init__.py", line 357, in loads
    return _default_decoder.decode(s)
  File "/usr/local/lib/python3.8/json/decoder.py", line 337, in decode
    obj, end = self.raw_decode(s, idx=_w(s, 0).end())
  File "/usr/local/lib/python3.8/json/decoder.py", line 355, in raw_decode
    raise JSONDecodeError("Expecting value", s, err.value) from None
json.decoder.JSONDecodeError: Expecting value: line 1 column 1 (char 0)

During handling of the above exception, another exception occurred:

Traceback (most recent call last):
  File "/home/airflow/.local/lib/python3.8/site-packages/airflow/models/taskinstance.py", line 433, in _execute_task
    result = execute_callable(context=context, **execute_callable_kwargs)
  File "/home/airflow/.local/lib/python3.8/site-packages/airflow/providers/google/cloud/transfers/gcs_to_bigquery.py", line 380, in execute
    self.configuration = self._use_existing_table()
  File "/home/airflow/.local/lib/python3.8/site-packages/airflow/providers/google/cloud/transfers/gcs_to_bigquery.py", line 581, in _use_existing_table
    default_project_id=self.hook.project_id,
  File "/home/airflow/.local/lib/python3.8/site-packages/airflow/providers/google/common/hooks/base_google.py", line 361, in project_id
    _, project_id = self.get_credentials_and_project_id()
  File "/home/airflow/.local/lib/python3.8/site-packages/airflow/providers/google/common/hooks/base_google.py", line 261, in get_credentials_and_project_id
    raise AirflowException("Invalid key JSON.")
airflow.exceptions.AirflowException: Invalid key JSON.
[2024-02-20T20:45:59.230+0000] {taskinstance.py:1138} INFO - Marking task as UP_FOR_RETRY. dag_id=processing_sales, task_id=load_data_to_bronze, execution_date=20220801T010000, start_date=20240220T204559, end_date=20240220T204559
[2024-02-20T20:45:59.239+0000] {standard_task_runner.py:107} ERROR - Failed to execute job 8 for task load_data_to_bronze (Invalid key JSON.; 1954)
[2024-02-20T20:45:59.274+0000] {local_task_job_runner.py:234} INFO - Task exited with return code 1
[2024-02-20T20:45:59.293+0000] {taskinstance.py:3281} INFO - 0 downstream tasks scheduled from follow-on schedule check
[2024-02-20T21:08:32.411+0000] {taskinstance.py:1957} INFO - Dependencies all met for dep_context=non-requeueable deps ti=<TaskInstance: processing_sales.load_data_to_bronze scheduled__2022-08-01T01:00:00+00:00 [queued]>
[2024-02-20T21:08:32.422+0000] {taskinstance.py:1957} INFO - Dependencies all met for dep_context=requeueable deps ti=<TaskInstance: processing_sales.load_data_to_bronze scheduled__2022-08-01T01:00:00+00:00 [queued]>
[2024-02-20T21:08:32.423+0000] {taskinstance.py:2171} INFO - Starting attempt 3 of 6
[2024-02-20T21:08:32.439+0000] {taskinstance.py:2192} INFO - Executing <Task(GCSToBigQueryOperator): load_data_to_bronze> on 2022-08-01 01:00:00+00:00
[2024-02-20T21:08:32.444+0000] {standard_task_runner.py:60} INFO - Started process 2734 to run task
[2024-02-20T21:08:32.448+0000] {standard_task_runner.py:87} INFO - Running: ['***', 'tasks', 'run', 'processing_sales', 'load_data_to_bronze', 'scheduled__2022-08-01T01:00:00+00:00', '--job-id', '14', '--raw', '--subdir', 'DAGS_FOLDER/process_sales.py', '--cfg-path', '/tmp/tmpo5zfj92u']
[2024-02-20T21:08:32.449+0000] {standard_task_runner.py:88} INFO - Job 14: Subtask load_data_to_bronze
[2024-02-20T21:08:32.505+0000] {task_command.py:423} INFO - Running <TaskInstance: processing_sales.load_data_to_bronze scheduled__2022-08-01T01:00:00+00:00 [running]> on host 483c6a14d6cc
[2024-02-20T21:08:32.582+0000] {taskinstance.py:2481} INFO - Exporting env vars: AIRFLOW_CTX_DAG_OWNER='***' AIRFLOW_CTX_DAG_ID='processing_sales' AIRFLOW_CTX_TASK_ID='load_data_to_bronze' AIRFLOW_CTX_EXECUTION_DATE='2022-08-01T01:00:00+00:00' AIRFLOW_CTX_TRY_NUMBER='3' AIRFLOW_CTX_DAG_RUN_ID='scheduled__2022-08-01T01:00:00+00:00'
[2024-02-20T21:08:32.594+0000] {connection.py:234} WARNING - Connection schemes (type: google_cloud_platform) shall not contain '_' according to RFC3986.
[2024-02-20T21:08:32.596+0000] {base.py:83} INFO - Using connection ID 'google-cloud' for task execution.
[2024-02-20T21:08:32.597+0000] {gcs_to_bigquery.py:379} INFO - Using existing BigQuery table for storing data...
[2024-02-20T21:08:32.598+0000] {logging_mixin.py:188} INFO - Expecting value: line 1 column 1 (char 0)
[2024-02-20T21:08:32.607+0000] {taskinstance.py:2699} ERROR - Task failed with exception
Traceback (most recent call last):
  File "/home/airflow/.local/lib/python3.8/site-packages/airflow/providers/google/common/hooks/base_google.py", line 259, in get_credentials_and_project_id
    keyfile_dict_json = json.loads(keyfile_dict)
  File "/usr/local/lib/python3.8/json/__init__.py", line 357, in loads
    return _default_decoder.decode(s)
  File "/usr/local/lib/python3.8/json/decoder.py", line 337, in decode
    obj, end = self.raw_decode(s, idx=_w(s, 0).end())
  File "/usr/local/lib/python3.8/json/decoder.py", line 355, in raw_decode
    raise JSONDecodeError("Expecting value", s, err.value) from None
json.decoder.JSONDecodeError: Expecting value: line 1 column 1 (char 0)

During handling of the above exception, another exception occurred:

Traceback (most recent call last):
  File "/home/airflow/.local/lib/python3.8/site-packages/airflow/models/taskinstance.py", line 433, in _execute_task
    result = execute_callable(context=context, **execute_callable_kwargs)
  File "/home/airflow/.local/lib/python3.8/site-packages/airflow/providers/google/cloud/transfers/gcs_to_bigquery.py", line 380, in execute
    self.configuration = self._use_existing_table()
  File "/home/airflow/.local/lib/python3.8/site-packages/airflow/providers/google/cloud/transfers/gcs_to_bigquery.py", line 581, in _use_existing_table
    default_project_id=self.hook.project_id,
  File "/home/airflow/.local/lib/python3.8/site-packages/airflow/providers/google/common/hooks/base_google.py", line 362, in project_id
    _, project_id = self.get_credentials_and_project_id()
  File "/home/airflow/.local/lib/python3.8/site-packages/airflow/providers/google/common/hooks/base_google.py", line 262, in get_credentials_and_project_id
    raise AirflowException("Invalid key JSON.")
airflow.exceptions.AirflowException: Invalid key JSON.
[2024-02-20T21:08:32.611+0000] {taskinstance.py:1138} INFO - Marking task as UP_FOR_RETRY. dag_id=processing_sales, task_id=load_data_to_bronze, execution_date=20220801T010000, start_date=20240220T210832, end_date=20240220T210832
[2024-02-20T21:08:32.625+0000] {standard_task_runner.py:107} ERROR - Failed to execute job 14 for task load_data_to_bronze (Invalid key JSON.; 2734)
[2024-02-20T21:08:32.661+0000] {local_task_job_runner.py:234} INFO - Task exited with return code 1
[2024-02-20T21:08:32.687+0000] {taskinstance.py:3281} INFO - 0 downstream tasks scheduled from follow-on schedule check
[2024-02-20T21:15:26.977+0000] {taskinstance.py:1957} INFO - Dependencies all met for dep_context=non-requeueable deps ti=<TaskInstance: processing_sales.load_data_to_bronze scheduled__2022-08-01T01:00:00+00:00 [queued]>
[2024-02-20T21:15:26.989+0000] {taskinstance.py:1957} INFO - Dependencies all met for dep_context=requeueable deps ti=<TaskInstance: processing_sales.load_data_to_bronze scheduled__2022-08-01T01:00:00+00:00 [queued]>
[2024-02-20T21:15:26.990+0000] {taskinstance.py:2171} INFO - Starting attempt 3 of 6
[2024-02-20T21:15:27.010+0000] {taskinstance.py:2192} INFO - Executing <Task(GCSToBigQueryOperator): load_data_to_bronze> on 2022-08-01 01:00:00+00:00
[2024-02-20T21:15:27.016+0000] {standard_task_runner.py:60} INFO - Started process 2851 to run task
[2024-02-20T21:15:27.021+0000] {standard_task_runner.py:87} INFO - Running: ['***', 'tasks', 'run', 'processing_sales', 'load_data_to_bronze', 'scheduled__2022-08-01T01:00:00+00:00', '--job-id', '17', '--raw', '--subdir', 'DAGS_FOLDER/process_sales.py', '--cfg-path', '/tmp/tmp7ogdfe1w']
[2024-02-20T21:15:27.023+0000] {standard_task_runner.py:88} INFO - Job 17: Subtask load_data_to_bronze
[2024-02-20T21:15:27.097+0000] {task_command.py:423} INFO - Running <TaskInstance: processing_sales.load_data_to_bronze scheduled__2022-08-01T01:00:00+00:00 [running]> on host 483c6a14d6cc
[2024-02-20T21:15:27.200+0000] {taskinstance.py:2481} INFO - Exporting env vars: AIRFLOW_CTX_DAG_OWNER='***' AIRFLOW_CTX_DAG_ID='processing_sales' AIRFLOW_CTX_TASK_ID='load_data_to_bronze' AIRFLOW_CTX_EXECUTION_DATE='2022-08-01T01:00:00+00:00' AIRFLOW_CTX_TRY_NUMBER='3' AIRFLOW_CTX_DAG_RUN_ID='scheduled__2022-08-01T01:00:00+00:00'
[2024-02-20T21:15:27.217+0000] {connection.py:234} WARNING - Connection schemes (type: google_cloud_platform) shall not contain '_' according to RFC3986.
[2024-02-20T21:15:27.218+0000] {base.py:83} INFO - Using connection ID 'google-cloud' for task execution.
[2024-02-20T21:15:27.220+0000] {gcs_to_bigquery.py:379} INFO - Using existing BigQuery table for storing data...
[2024-02-20T21:15:27.221+0000] {logging_mixin.py:188} INFO - BEFORE
[2024-02-20T21:15:27.221+0000] {logging_mixin.py:188} INFO - ***
[2024-02-20T21:15:27.222+0000] {logging_mixin.py:188} INFO - <class 'str'>
[2024-02-20T21:15:27.223+0000] {logging_mixin.py:188} INFO - /opt/***/config/credentials.json
[2024-02-20T21:15:27.223+0000] {logging_mixin.py:188} INFO - AFTER
[2024-02-20T21:15:27.224+0000] {logging_mixin.py:188} INFO - Expecting value: line 1 column 1 (char 0)
[2024-02-20T21:15:27.234+0000] {taskinstance.py:2699} ERROR - Task failed with exception
Traceback (most recent call last):
  File "/home/airflow/.local/lib/python3.8/site-packages/airflow/providers/google/common/hooks/base_google.py", line 263, in get_credentials_and_project_id
    keyfile_dict_json = json.loads(keyfile_dict)
  File "/usr/local/lib/python3.8/json/__init__.py", line 357, in loads
    return _default_decoder.decode(s)
  File "/usr/local/lib/python3.8/json/decoder.py", line 337, in decode
    obj, end = self.raw_decode(s, idx=_w(s, 0).end())
  File "/usr/local/lib/python3.8/json/decoder.py", line 355, in raw_decode
    raise JSONDecodeError("Expecting value", s, err.value) from None
json.decoder.JSONDecodeError: Expecting value: line 1 column 1 (char 0)

During handling of the above exception, another exception occurred:

Traceback (most recent call last):
  File "/home/airflow/.local/lib/python3.8/site-packages/airflow/models/taskinstance.py", line 433, in _execute_task
    result = execute_callable(context=context, **execute_callable_kwargs)
  File "/home/airflow/.local/lib/python3.8/site-packages/airflow/providers/google/cloud/transfers/gcs_to_bigquery.py", line 380, in execute
    self.configuration = self._use_existing_table()
  File "/home/airflow/.local/lib/python3.8/site-packages/airflow/providers/google/cloud/transfers/gcs_to_bigquery.py", line 581, in _use_existing_table
    default_project_id=self.hook.project_id,
  File "/home/airflow/.local/lib/python3.8/site-packages/airflow/providers/google/common/hooks/base_google.py", line 366, in project_id
    _, project_id = self.get_credentials_and_project_id()
  File "/home/airflow/.local/lib/python3.8/site-packages/airflow/providers/google/common/hooks/base_google.py", line 266, in get_credentials_and_project_id
    raise AirflowException("Invalid key JSON. wazaaaaaap")
airflow.exceptions.AirflowException: Invalid key JSON. wazaaaaaap
[2024-02-20T21:15:27.241+0000] {taskinstance.py:1138} INFO - Marking task as UP_FOR_RETRY. dag_id=processing_sales, task_id=load_data_to_bronze, execution_date=20220801T010000, start_date=20240220T211526, end_date=20240220T211527
[2024-02-20T21:15:27.290+0000] {standard_task_runner.py:107} ERROR - Failed to execute job 17 for task load_data_to_bronze (Invalid key JSON. wazaaaaaap; 2851)
[2024-02-20T21:15:27.313+0000] {local_task_job_runner.py:234} INFO - Task exited with return code 1
[2024-02-20T21:15:27.344+0000] {taskinstance.py:3281} INFO - 0 downstream tasks scheduled from follow-on schedule check
