[2024-02-20T21:28:13.855+0000] {taskinstance.py:1957} INFO - Dependencies all met for dep_context=non-requeueable deps ti=<TaskInstance: processing_sales.load_data_to_bronze scheduled__2022-08-01T01:00:00+00:00 [queued]>
[2024-02-20T21:28:13.866+0000] {taskinstance.py:1957} INFO - Dependencies all met for dep_context=requeueable deps ti=<TaskInstance: processing_sales.load_data_to_bronze scheduled__2022-08-01T01:00:00+00:00 [queued]>
[2024-02-20T21:28:13.867+0000] {taskinstance.py:2171} INFO - Starting attempt 12 of 15
[2024-02-20T21:28:13.886+0000] {taskinstance.py:2192} INFO - Executing <Task(GCSToBigQueryOperator): load_data_to_bronze> on 2022-08-01 01:00:00+00:00
[2024-02-20T21:28:13.892+0000] {standard_task_runner.py:60} INFO - Started process 935 to run task
[2024-02-20T21:28:13.897+0000] {standard_task_runner.py:87} INFO - Running: ['***', 'tasks', 'run', 'processing_sales', 'load_data_to_bronze', 'scheduled__2022-08-01T01:00:00+00:00', '--job-id', '26', '--raw', '--subdir', 'DAGS_FOLDER/process_sales.py', '--cfg-path', '/tmp/tmpw202stn4']
[2024-02-20T21:28:13.899+0000] {standard_task_runner.py:88} INFO - Job 26: Subtask load_data_to_bronze
[2024-02-20T21:28:13.960+0000] {task_command.py:423} INFO - Running <TaskInstance: processing_sales.load_data_to_bronze scheduled__2022-08-01T01:00:00+00:00 [running]> on host 14ee3b1c5c12
[2024-02-20T21:28:14.060+0000] {taskinstance.py:2481} INFO - Exporting env vars: AIRFLOW_CTX_DAG_OWNER='***' AIRFLOW_CTX_DAG_ID='processing_sales' AIRFLOW_CTX_TASK_ID='load_data_to_bronze' AIRFLOW_CTX_EXECUTION_DATE='2022-08-01T01:00:00+00:00' AIRFLOW_CTX_TRY_NUMBER='12' AIRFLOW_CTX_DAG_RUN_ID='scheduled__2022-08-01T01:00:00+00:00'
[2024-02-20T21:28:14.076+0000] {connection.py:234} WARNING - Connection schemes (type: google_cloud_platform) shall not contain '_' according to RFC3986.
[2024-02-20T21:28:14.078+0000] {base.py:83} INFO - Using connection ID 'google-cloud' for task execution.
[2024-02-20T21:28:14.079+0000] {gcs_to_bigquery.py:379} INFO - Using existing BigQuery table for storing data...
[2024-02-20T21:28:14.080+0000] {logging_mixin.py:188} INFO - VEFORE
[2024-02-20T21:28:14.080+0000] {logging_mixin.py:188} INFO - airf
[2024-02-20T21:28:14.081+0000] {logging_mixin.py:188} INFO - ***
[2024-02-20T21:28:14.091+0000] {taskinstance.py:2699} ERROR - Task failed with exception
Traceback (most recent call last):
  File "/home/airflow/.local/lib/python3.8/site-packages/airflow/providers/google/common/hooks/base_google.py", line 265, in get_credentials_and_project_id
    keyfile_dict_json = json.loads(keyfile_dict)
  File "/usr/local/lib/python3.8/json/__init__.py", line 357, in loads
    return _default_decoder.decode(s)
  File "/usr/local/lib/python3.8/json/decoder.py", line 337, in decode
    obj, end = self.raw_decode(s, idx=_w(s, 0).end())
  File "/usr/local/lib/python3.8/json/decoder.py", line 355, in raw_decode
    raise JSONDecodeError("Expecting value", s, err.value) from None
json.decoder.JSONDecodeError: Expecting value: line 1 column 1 (char 0)

During handling of the above exception, another exception occurred:

Traceback (most recent call last):
  File "/home/airflow/.local/lib/python3.8/site-packages/airflow/models/taskinstance.py", line 433, in _execute_task
    result = execute_callable(context=context, **execute_callable_kwargs)
  File "/home/airflow/.local/lib/python3.8/site-packages/airflow/providers/google/cloud/transfers/gcs_to_bigquery.py", line 380, in execute
    self.configuration = self._use_existing_table()
  File "/home/airflow/.local/lib/python3.8/site-packages/airflow/providers/google/cloud/transfers/gcs_to_bigquery.py", line 581, in _use_existing_table
    default_project_id=self.hook.project_id,
  File "/home/airflow/.local/lib/python3.8/site-packages/airflow/providers/google/common/hooks/base_google.py", line 367, in project_id
    _, project_id = self.get_credentials_and_project_id()
  File "/home/airflow/.local/lib/python3.8/site-packages/airflow/providers/google/common/hooks/base_google.py", line 267, in get_credentials_and_project_id
    raise AirflowException("Invalid key JSON.")
airflow.exceptions.AirflowException: Invalid key JSON.
[2024-02-20T21:28:14.097+0000] {taskinstance.py:1138} INFO - Marking task as UP_FOR_RETRY. dag_id=processing_sales, task_id=load_data_to_bronze, execution_date=20220801T010000, start_date=20240220T212813, end_date=20240220T212814
[2024-02-20T21:28:14.148+0000] {standard_task_runner.py:107} ERROR - Failed to execute job 26 for task load_data_to_bronze (Invalid key JSON.; 935)
[2024-02-20T21:28:14.190+0000] {local_task_job_runner.py:234} INFO - Task exited with return code 1
[2024-02-20T21:28:14.216+0000] {taskinstance.py:3281} INFO - 0 downstream tasks scheduled from follow-on schedule check
